Log Entry : 
9/8/2019 9:47:46 AM
  :
  :Amazon.CloudWatchLogs.Model.ResourceAlreadyExistsException: The specified log stream already exists ---> Amazon.Runtime.Internal.HttpErrorResponseException: The remote server returned an error: (400) Bad Request. ---> System.Net.WebException: The remote server returned an error: (400) Bad Request.
   at System.Net.HttpWebRequest.EndGetResponse(IAsyncResult asyncResult)
   at System.Threading.Tasks.TaskFactory`1.FromAsyncCoreLogic(IAsyncResult iar, Func`2 endFunction, Action`1 endAction, Task`1 promise, Boolean requiresSynchronization)
--- End of stack trace from previous location where exception was thrown ---
   at System.Runtime.ExceptionServices.ExceptionDispatchInfo.Throw()
   at System.Runtime.CompilerServices.TaskAwaiter.HandleNonSuccessAndDebuggerNotification(Task task)
   at Amazon.Runtime.Internal.HttpRequest.<GetResponseAsync>d__16.MoveNext()
   --- End of inner exception stack trace ---
   at Amazon.Runtime.Internal.HttpRequest.<GetResponseAsync>d__16.MoveNext()
--- End of stack trace from previous location where exception was thrown ---
   at System.Runtime.ExceptionServices.ExceptionDispatchInfo.Throw()
   at System.Runtime.CompilerServices.TaskAwaiter.HandleNonSuccessAndDebuggerNotification(Task task)
   at Amazon.Runtime.Internal.HttpHandler`1.<InvokeAsync>d__9`1.MoveNext()
--- End of stack trace from previous location where exception was thrown ---
   at System.Runtime.ExceptionServices.ExceptionDispatchInfo.Throw()
   at System.Runtime.CompilerServices.TaskAwaiter.HandleNonSuccessAndDebuggerNotification(Task task)
   at Amazon.Runtime.Internal.Unmarshaller.<InvokeAsync>d__3`1.MoveNext()
--- End of stack trace from previous location where exception was thrown ---
   at System.Runtime.ExceptionServices.ExceptionDispatchInfo.Throw()
   at System.Runtime.CompilerServices.TaskAwaiter.HandleNonSuccessAndDebuggerNotification(Task task)
   at Amazon.Runtime.Internal.ErrorHandler.<InvokeAsync>d__5`1.MoveNext()
   --- End of inner exception stack trace ---
   at Amazon.Runtime.Internal.HttpErrorResponseExceptionHandler.HandleException(IExecutionContext executionContext, HttpErrorResponseException exception)
   at Amazon.Runtime.Internal.ErrorHandler.ProcessException(IExecutionContext executionContext, Exception exception)
   at Amazon.Runtime.Internal.ErrorHandler.<InvokeAsync>d__5`1.MoveNext()
--- End of stack trace from previous location where exception was thrown ---
   at System.Runtime.ExceptionServices.ExceptionDispatchInfo.Throw()
   at System.Runtime.CompilerServices.TaskAwaiter.HandleNonSuccessAndDebuggerNotification(Task task)
   at Amazon.Runtime.Internal.CallbackHandler.<InvokeAsync>d__9`1.MoveNext()
--- End of stack trace from previous location where exception was thrown ---
   at System.Runtime.ExceptionServices.ExceptionDispatchInfo.Throw()
   at System.Runtime.CompilerServices.TaskAwaiter.HandleNonSuccessAndDebuggerNotification(Task task)
   at Amazon.Runtime.Internal.EndpointDiscoveryHandler.<InvokeAsync>d__2`1.MoveNext()
--- End of stack trace from previous location where exception was thrown ---
   at System.Runtime.ExceptionServices.ExceptionDispatchInfo.Throw()
   at Amazon.Runtime.Internal.EndpointDiscoveryHandler.<InvokeAsync>d__2`1.MoveNext()
--- End of stack trace from previous location where exception was thrown ---
   at System.Runtime.ExceptionServices.ExceptionDispatchInfo.Throw()
   at System.Runtime.CompilerServices.TaskAwaiter.HandleNonSuccessAndDebuggerNotification(Task task)
   at Amazon.Runtime.Internal.CredentialsRetriever.<InvokeAsync>d__7`1.MoveNext()
--- End of stack trace from previous location where exception was thrown ---
   at System.Runtime.ExceptionServices.ExceptionDispatchInfo.Throw()
   at System.Runtime.CompilerServices.TaskAwaiter.HandleNonSuccessAndDebuggerNotification(Task task)
   at Amazon.Runtime.Internal.RetryHandler.<InvokeAsync>d__10`1.MoveNext()
--- End of stack trace from previous location where exception was thrown ---
   at System.Runtime.ExceptionServices.ExceptionDispatchInfo.Throw()
   at Amazon.Runtime.Internal.RetryHandler.<InvokeAsync>d__10`1.MoveNext()
--- End of stack trace from previous location where exception was thrown ---
   at System.Runtime.ExceptionServices.ExceptionDispatchInfo.Throw()
   at System.Runtime.CompilerServices.TaskAwaiter.HandleNonSuccessAndDebuggerNotification(Task task)
   at Amazon.Runtime.Internal.CallbackHandler.<InvokeAsync>d__9`1.MoveNext()
--- End of stack trace from previous location where exception was thrown ---
   at System.Runtime.ExceptionServices.ExceptionDispatchInfo.Throw()
   at System.Runtime.CompilerServices.TaskAwaiter.HandleNonSuccessAndDebuggerNotification(Task task)
   at Amazon.Runtime.Internal.CallbackHandler.<InvokeAsync>d__9`1.MoveNext()
--- End of stack trace from previous location where exception was thrown ---
   at System.Runtime.ExceptionServices.ExceptionDispatchInfo.Throw()
   at System.Runtime.CompilerServices.TaskAwaiter.HandleNonSuccessAndDebuggerNotification(Task task)
   at Amazon.Runtime.Internal.ErrorCallbackHandler.<InvokeAsync>d__5`1.MoveNext()
-------------------------------
Log Entry : 
9/8/2019 9:47:46 AM
  :
  :Amazon.CloudWatchLogs.Model.ResourceAlreadyExistsException: The specified log stream already exists ---> Amazon.Runtime.Internal.HttpErrorResponseException: The remote server returned an error: (400) Bad Request. ---> System.Net.WebException: The remote server returned an error: (400) Bad Request.
   at System.Net.HttpWebRequest.EndGetResponse(IAsyncResult asyncResult)
   at System.Threading.Tasks.TaskFactory`1.FromAsyncCoreLogic(IAsyncResult iar, Func`2 endFunction, Action`1 endAction, Task`1 promise, Boolean requiresSynchronization)
--- End of stack trace from previous location where exception was thrown ---
   at System.Runtime.ExceptionServices.ExceptionDispatchInfo.Throw()
   at System.Runtime.CompilerServices.TaskAwaiter.HandleNonSuccessAndDebuggerNotification(Task task)
   at Amazon.Runtime.Internal.HttpRequest.<GetResponseAsync>d__16.MoveNext()
   --- End of inner exception stack trace ---
   at Amazon.Runtime.Internal.HttpRequest.<GetResponseAsync>d__16.MoveNext()
--- End of stack trace from previous location where exception was thrown ---
   at System.Runtime.ExceptionServices.ExceptionDispatchInfo.Throw()
   at System.Runtime.CompilerServices.TaskAwaiter.HandleNonSuccessAndDebuggerNotification(Task task)
   at Amazon.Runtime.Internal.HttpHandler`1.<InvokeAsync>d__9`1.MoveNext()
--- End of stack trace from previous location where exception was thrown ---
   at System.Runtime.ExceptionServices.ExceptionDispatchInfo.Throw()
   at System.Runtime.CompilerServices.TaskAwaiter.HandleNonSuccessAndDebuggerNotification(Task task)
   at Amazon.Runtime.Internal.Unmarshaller.<InvokeAsync>d__3`1.MoveNext()
--- End of stack trace from previous location where exception was thrown ---
   at System.Runtime.ExceptionServices.ExceptionDispatchInfo.Throw()
   at System.Runtime.CompilerServices.TaskAwaiter.HandleNonSuccessAndDebuggerNotification(Task task)
   at Amazon.Runtime.Internal.ErrorHandler.<InvokeAsync>d__5`1.MoveNext()
   --- End of inner exception stack trace ---
   at Amazon.Runtime.Internal.HttpErrorResponseExceptionHandler.HandleException(IExecutionContext executionContext, HttpErrorResponseException exception)
   at Amazon.Runtime.Internal.ErrorHandler.ProcessException(IExecutionContext executionContext, Exception exception)
   at Amazon.Runtime.Internal.ErrorHandler.<InvokeAsync>d__5`1.MoveNext()
--- End of stack trace from previous location where exception was thrown ---
   at System.Runtime.ExceptionServices.ExceptionDispatchInfo.Throw()
   at System.Runtime.CompilerServices.TaskAwaiter.HandleNonSuccessAndDebuggerNotification(Task task)
   at Amazon.Runtime.Internal.CallbackHandler.<InvokeAsync>d__9`1.MoveNext()
--- End of stack trace from previous location where exception was thrown ---
   at System.Runtime.ExceptionServices.ExceptionDispatchInfo.Throw()
   at System.Runtime.CompilerServices.TaskAwaiter.HandleNonSuccessAndDebuggerNotification(Task task)
   at Amazon.Runtime.Internal.EndpointDiscoveryHandler.<InvokeAsync>d__2`1.MoveNext()
--- End of stack trace from previous location where exception was thrown ---
   at System.Runtime.ExceptionServices.ExceptionDispatchInfo.Throw()
   at Amazon.Runtime.Internal.EndpointDiscoveryHandler.<InvokeAsync>d__2`1.MoveNext()
--- End of stack trace from previous location where exception was thrown ---
   at System.Runtime.ExceptionServices.ExceptionDispatchInfo.Throw()
   at System.Runtime.CompilerServices.TaskAwaiter.HandleNonSuccessAndDebuggerNotification(Task task)
   at Amazon.Runtime.Internal.CredentialsRetriever.<InvokeAsync>d__7`1.MoveNext()
--- End of stack trace from previous location where exception was thrown ---
   at System.Runtime.ExceptionServices.ExceptionDispatchInfo.Throw()
   at System.Runtime.CompilerServices.TaskAwaiter.HandleNonSuccessAndDebuggerNotification(Task task)
   at Amazon.Runtime.Internal.RetryHandler.<InvokeAsync>d__10`1.MoveNext()
--- End of stack trace from previous location where exception was thrown ---
   at System.Runtime.ExceptionServices.ExceptionDispatchInfo.Throw()
   at Amazon.Runtime.Internal.RetryHandler.<InvokeAsync>d__10`1.MoveNext()
--- End of stack trace from previous location where exception was thrown ---
   at System.Runtime.ExceptionServices.ExceptionDispatchInfo.Throw()
   at System.Runtime.CompilerServices.TaskAwaiter.HandleNonSuccessAndDebuggerNotification(Task task)
   at Amazon.Runtime.Internal.CallbackHandler.<InvokeAsync>d__9`1.MoveNext()
--- End of stack trace from previous location where exception was thrown ---
   at System.Runtime.ExceptionServices.ExceptionDispatchInfo.Throw()
   at System.Runtime.CompilerServices.TaskAwaiter.HandleNonSuccessAndDebuggerNotification(Task task)
   at Amazon.Runtime.Internal.CallbackHandler.<InvokeAsync>d__9`1.MoveNext()
--- End of stack trace from previous location where exception was thrown ---
   at System.Runtime.ExceptionServices.ExceptionDispatchInfo.Throw()
   at System.Runtime.CompilerServices.TaskAwaiter.HandleNonSuccessAndDebuggerNotification(Task task)
   at Amazon.Runtime.Internal.ErrorCallbackHandler.<InvokeAsync>d__5`1.MoveNext()
--- End of stack trace from previous location where exception was thrown ---
   at System.Runtime.ExceptionServices.ExceptionDispatchInfo.Throw()
   at System.Runtime.CompilerServices.TaskAwaiter.HandleNonSuccessAndDebuggerNotification(Task task)
   at Amazon.Runtime.Internal.MetricsHandler.<InvokeAsync>d__1`1.MoveNext()
--- End of stack trace from previous location where exception was thrown ---
   at System.Runtime.ExceptionServices.ExceptionDispatchInfo.Throw()
   at System.Runtime.CompilerServices.TaskAwaiter.HandleNonSuccessAndDebuggerNotification(Task task)
   at AWS.Logger.Core.AWSLoggerCore.<LogEventTransmissionSetup>d__33.MoveNext()
--- End of stack trace from previous location where exception was thrown ---
   at System.Runtime.ExceptionServices.ExceptionDispatchInfo.Throw()
   at System.Runtime.CompilerServices.TaskAwaiter.HandleNonSuccessAndDebuggerNotification(Task task)
   at AWS.Logger.Core.AWSLoggerCore.<Monitor>d__31.MoveNext()
-------------------------------
Log Entry : 
9/8/2019 9:47:46 AM
  :
  :Amazon.CloudWatchLogs.Model.ResourceAlreadyExistsException: The specified log stream already exists ---> Amazon.Runtime.Internal.HttpErrorResponseException: The remote server returned an error: (400) Bad Request. ---> System.Net.WebException: The remote server returned an error: (400) Bad Request.
   at System.Net.HttpWebRequest.EndGetResponse(IAsyncResult asyncResult)
   at System.Threading.Tasks.TaskFactory`1.FromAsyncCoreLogic(IAsyncResult iar, Func`2 endFunction, Action`1 endAction, Task`1 promise, Boolean requiresSynchronization)
--- End of stack trace from previous location where exception was thrown ---
   at System.Runtime.ExceptionServices.ExceptionDispatchInfo.Throw()
   at System.Runtime.CompilerServices.TaskAwaiter.HandleNonSuccessAndDebuggerNotification(Task task)
   at Amazon.Runtime.Internal.HttpRequest.<GetResponseAsync>d__16.MoveNext()
   --- End of inner exception stack trace ---
   at Amazon.Runtime.Internal.HttpRequest.<GetResponseAsync>d__16.MoveNext()
--- End of stack trace from previous location where exception was thrown ---
   at System.Runtime.ExceptionServices.ExceptionDispatchInfo.Throw()
   at System.Runtime.CompilerServices.TaskAwaiter.HandleNonSuccessAndDebuggerNotification(Task task)
   at Amazon.Runtime.Internal.HttpHandler`1.<InvokeAsync>d__9`1.MoveNext()
--- End of stack trace from previous location where exception was thrown ---
   at System.Runtime.ExceptionServices.ExceptionDispatchInfo.Throw()
   at System.Runtime.CompilerServices.TaskAwaiter.HandleNonSuccessAndDebuggerNotification(Task task)
   at Amazon.Runtime.Internal.Unmarshaller.<InvokeAsync>d__3`1.MoveNext()
--- End of stack trace from previous location where exception was thrown ---
   at System.Runtime.ExceptionServices.ExceptionDispatchInfo.Throw()
   at System.Runtime.CompilerServices.TaskAwaiter.HandleNonSuccessAndDebuggerNotification(Task task)
   at Amazon.Runtime.Internal.ErrorHandler.<InvokeAsync>d__5`1.MoveNext()
   --- End of inner exception stack trace ---
   at Amazon.Runtime.Internal.HttpErrorResponseExceptionHandler.HandleException(IExecutionContext executionContext, HttpErrorResponseException exception)
   at Amazon.Runtime.Internal.ErrorHandler.ProcessException(IExecutionContext executionContext, Exception exception)
   at Amazon.Runtime.Internal.ErrorHandler.<InvokeAsync>d__5`1.MoveNext()
--- End of stack trace from previous location where exception was thrown ---
   at System.Runtime.ExceptionServices.ExceptionDispatchInfo.Throw()
   at System.Runtime.CompilerServices.TaskAwaiter.HandleNonSuccessAndDebuggerNotification(Task task)
   at Amazon.Runtime.Internal.CallbackHandler.<InvokeAsync>d__9`1.MoveNext()
--- End of stack trace from previous location where exception was thrown ---
   at System.Runtime.ExceptionServices.ExceptionDispatchInfo.Throw()
   at System.Runtime.CompilerServices.TaskAwaiter.HandleNonSuccessAndDebuggerNotification(Task task)
   at Amazon.Runtime.Internal.EndpointDiscoveryHandler.<InvokeAsync>d__2`1.MoveNext()
--- End of stack trace from previous location where exception was thrown ---
   at System.Runtime.ExceptionServices.ExceptionDispatchInfo.Throw()
   at Amazon.Runtime.Internal.EndpointDiscoveryHandler.<InvokeAsync>d__2`1.MoveNext()
--- End of stack trace from previous location where exception was thrown ---
   at System.Runtime.ExceptionServices.ExceptionDispatchInfo.Throw()
   at System.Runtime.CompilerServices.TaskAwaiter.HandleNonSuccessAndDebuggerNotification(Task task)
   at Amazon.Runtime.Internal.CredentialsRetriever.<InvokeAsync>d__7`1.MoveNext()
--- End of stack trace from previous location where exception was thrown ---
   at System.Runtime.ExceptionServices.ExceptionDispatchInfo.Throw()
   at System.Runtime.CompilerServices.TaskAwaiter.HandleNonSuccessAndDebuggerNotification(Task task)
   at Amazon.Runtime.Internal.RetryHandler.<InvokeAsync>d__10`1.MoveNext()
--- End of stack trace from previous location where exception was thrown ---
   at System.Runtime.ExceptionServices.ExceptionDispatchInfo.Throw()
   at Amazon.Runtime.Internal.RetryHandler.<InvokeAsync>d__10`1.MoveNext()
--- End of stack trace from previous location where exception was thrown ---
   at System.Runtime.ExceptionServices.ExceptionDispatchInfo.Throw()
   at System.Runtime.CompilerServices.TaskAwaiter.HandleNonSuccessAndDebuggerNotification(Task task)
   at Amazon.Runtime.Internal.CallbackHandler.<InvokeAsync>d__9`1.MoveNext()
--- End of stack trace from previous location where exception was thrown ---
   at System.Runtime.ExceptionServices.ExceptionDispatchInfo.Throw()
   at System.Runtime.CompilerServices.TaskAwaiter.HandleNonSuccessAndDebuggerNotification(Task task)
   at Amazon.Runtime.Internal.CallbackHandler.<InvokeAsync>d__9`1.MoveNext()
--- End of stack trace from previous location where exception was thrown ---
   at System.Runtime.ExceptionServices.ExceptionDispatchInfo.Throw()
   at System.Runtime.CompilerServices.TaskAwaiter.HandleNonSuccessAndDebuggerNotification(Task task)
   at Amazon.Runtime.Internal.ErrorCallbackHandler.<InvokeAsync>d__5`1.MoveNext()
-------------------------------
Log Entry : 
9/8/2019 9:47:46 AM
  :
  :Amazon.CloudWatchLogs.Model.ResourceAlreadyExistsException: The specified log stream already exists ---> Amazon.Runtime.Internal.HttpErrorResponseException: The remote server returned an error: (400) Bad Request. ---> System.Net.WebException: The remote server returned an error: (400) Bad Request.
   at System.Net.HttpWebRequest.EndGetResponse(IAsyncResult asyncResult)
   at System.Threading.Tasks.TaskFactory`1.FromAsyncCoreLogic(IAsyncResult iar, Func`2 endFunction, Action`1 endAction, Task`1 promise, Boolean requiresSynchronization)
--- End of stack trace from previous location where exception was thrown ---
   at System.Runtime.ExceptionServices.ExceptionDispatchInfo.Throw()
   at System.Runtime.CompilerServices.TaskAwaiter.HandleNonSuccessAndDebuggerNotification(Task task)
   at Amazon.Runtime.Internal.HttpRequest.<GetResponseAsync>d__16.MoveNext()
   --- End of inner exception stack trace ---
   at Amazon.Runtime.Internal.HttpRequest.<GetResponseAsync>d__16.MoveNext()
--- End of stack trace from previous location where exception was thrown ---
   at System.Runtime.ExceptionServices.ExceptionDispatchInfo.Throw()
   at System.Runtime.CompilerServices.TaskAwaiter.HandleNonSuccessAndDebuggerNotification(Task task)
   at Amazon.Runtime.Internal.HttpHandler`1.<InvokeAsync>d__9`1.MoveNext()
--- End of stack trace from previous location where exception was thrown ---
   at System.Runtime.ExceptionServices.ExceptionDispatchInfo.Throw()
   at System.Runtime.CompilerServices.TaskAwaiter.HandleNonSuccessAndDebuggerNotification(Task task)
   at Amazon.Runtime.Internal.Unmarshaller.<InvokeAsync>d__3`1.MoveNext()
--- End of stack trace from previous location where exception was thrown ---
   at System.Runtime.ExceptionServices.ExceptionDispatchInfo.Throw()
   at System.Runtime.CompilerServices.TaskAwaiter.HandleNonSuccessAndDebuggerNotification(Task task)
   at Amazon.Runtime.Internal.ErrorHandler.<InvokeAsync>d__5`1.MoveNext()
   --- End of inner exception stack trace ---
   at Amazon.Runtime.Internal.HttpErrorResponseExceptionHandler.HandleException(IExecutionContext executionContext, HttpErrorResponseException exception)
   at Amazon.Runtime.Internal.ErrorHandler.ProcessException(IExecutionContext executionContext, Exception exception)
   at Amazon.Runtime.Internal.ErrorHandler.<InvokeAsync>d__5`1.MoveNext()
--- End of stack trace from previous location where exception was thrown ---
   at System.Runtime.ExceptionServices.ExceptionDispatchInfo.Throw()
   at System.Runtime.CompilerServices.TaskAwaiter.HandleNonSuccessAndDebuggerNotification(Task task)
   at Amazon.Runtime.Internal.CallbackHandler.<InvokeAsync>d__9`1.MoveNext()
--- End of stack trace from previous location where exception was thrown ---
   at System.Runtime.ExceptionServices.ExceptionDispatchInfo.Throw()
   at System.Runtime.CompilerServices.TaskAwaiter.HandleNonSuccessAndDebuggerNotification(Task task)
   at Amazon.Runtime.Internal.EndpointDiscoveryHandler.<InvokeAsync>d__2`1.MoveNext()
--- End of stack trace from previous location where exception was thrown ---
   at System.Runtime.ExceptionServices.ExceptionDispatchInfo.Throw()
   at Amazon.Runtime.Internal.EndpointDiscoveryHandler.<InvokeAsync>d__2`1.MoveNext()
--- End of stack trace from previous location where exception was thrown ---
   at System.Runtime.ExceptionServices.ExceptionDispatchInfo.Throw()
   at System.Runtime.CompilerServices.TaskAwaiter.HandleNonSuccessAndDebuggerNotification(Task task)
   at Amazon.Runtime.Internal.CredentialsRetriever.<InvokeAsync>d__7`1.MoveNext()
--- End of stack trace from previous location where exception was thrown ---
   at System.Runtime.ExceptionServices.ExceptionDispatchInfo.Throw()
   at System.Runtime.CompilerServices.TaskAwaiter.HandleNonSuccessAndDebuggerNotification(Task task)
   at Amazon.Runtime.Internal.RetryHandler.<InvokeAsync>d__10`1.MoveNext()
--- End of stack trace from previous location where exception was thrown ---
   at System.Runtime.ExceptionServices.ExceptionDispatchInfo.Throw()
   at Amazon.Runtime.Internal.RetryHandler.<InvokeAsync>d__10`1.MoveNext()
--- End of stack trace from previous location where exception was thrown ---
   at System.Runtime.ExceptionServices.ExceptionDispatchInfo.Throw()
   at System.Runtime.CompilerServices.TaskAwaiter.HandleNonSuccessAndDebuggerNotification(Task task)
   at Amazon.Runtime.Internal.CallbackHandler.<InvokeAsync>d__9`1.MoveNext()
--- End of stack trace from previous location where exception was thrown ---
   at System.Runtime.ExceptionServices.ExceptionDispatchInfo.Throw()
   at System.Runtime.CompilerServices.TaskAwaiter.HandleNonSuccessAndDebuggerNotification(Task task)
   at Amazon.Runtime.Internal.CallbackHandler.<InvokeAsync>d__9`1.MoveNext()
--- End of stack trace from previous location where exception was thrown ---
   at System.Runtime.ExceptionServices.ExceptionDispatchInfo.Throw()
   at System.Runtime.CompilerServices.TaskAwaiter.HandleNonSuccessAndDebuggerNotification(Task task)
   at Amazon.Runtime.Internal.ErrorCallbackHandler.<InvokeAsync>d__5`1.MoveNext()
--- End of stack trace from previous location where exception was thrown ---
   at System.Runtime.ExceptionServices.ExceptionDispatchInfo.Throw()
   at System.Runtime.CompilerServices.TaskAwaiter.HandleNonSuccessAndDebuggerNotification(Task task)
   at Amazon.Runtime.Internal.MetricsHandler.<InvokeAsync>d__1`1.MoveNext()
--- End of stack trace from previous location where exception was thrown ---
   at System.Runtime.ExceptionServices.ExceptionDispatchInfo.Throw()
   at System.Runtime.CompilerServices.TaskAwaiter.HandleNonSuccessAndDebuggerNotification(Task task)
   at AWS.Logger.Core.AWSLoggerCore.<LogEventTransmissionSetup>d__33.MoveNext()
--- End of stack trace from previous location where exception was thrown ---
   at System.Runtime.ExceptionServices.ExceptionDispatchInfo.Throw()
   at System.Runtime.CompilerServices.TaskAwaiter.HandleNonSuccessAndDebuggerNotification(Task task)
   at AWS.Logger.Core.AWSLoggerCore.<Monitor>d__31.MoveNext()
-------------------------------
